Workbook

Sheet Konfigurace
A1: FinanceFlow – Dluhový stres index (konfigurace)
A2: Modře/žlutě = editovatelné (váhy + prahy). Uprav a pošli zpět – synchronizuji do _STRESS_CFG v debts.js. Stres 0..váha (0=zdravé, váha=max stres); vyšší součet = horší. List „Bodování po rozmezích" ukazuje body pro konkrétní hodnoty.
A4: # | B4: Metrika | C4: Váha (b) | D4: Co měří | E4: Výpočet stresu | F4: Práh „zdravé" | G4: Práh „max stres" | H4: Klíč _STRESS_CFG
A5: 1 | B5: DSTI – zatížení příjmu | C5: 20 | D5: Splátky / měsíční příjem | E5: (1 − msc_DSTI/40) × váha | F5: dle tabulky msc_DSTI | G5: „banka zamítne" | H5: w.dsti
A6: 2 | B6: Emergency Fund | C6: 15 | D6: Měsíce PŘEŽITÍ BEZ PŘÍJMU: hotovost + likvidní rezerva (spořicí účet, term. vklad) / měsíční výdaje. NEZAHRNUJE investice (akcie/ETF) ani dlouhodobé (penzijko, DIP, nemovitosti). | E6: váha × (1 − měs./práh) | F6: ≥ 6 měsíců | G6: 0 měsíců | H6: emergencyMonthsFull
A7: 3 | B7: DTI – celková zadluženost | C7: 15 | D7: Dluh / roční příjem | E7: (1 − msc_DTI/60) × váha | F7: dle tabulky msc_DTI | G7: „banka zamítne" | H7: w.dti
A8: 4 | B8: Interest Cost Ratio | C8: 10 | D8: Úroky / měsíční příjem | E8: váha × poměr / práh | F8: 0 % | G8: ≥ 15 % příjmu | H8: interestCostMax
A9: 5 | B9: Debt Quality | C9: 10 | D9: Podíl drahého dluhu (objem) | E9: váha × podíl | F9: 0 % drahého | G9: 100 % drahého | H9: expensiveRate
A10: 6 | B10: Počet půjček | C10: 8 | D10: Počet aktivních půjček | E10: (počet−1) × 2, strop | F10: 1 půjčka | G10: ≥ 5 půjček | H10: w.loanCount
A11: 7 | B11: Vážený úrok | C11: 7 | D11: Σ(zůstatek×sazba)/Σzůstatek | E11: váha × (úrok−min)/(max−min) | F11: ≤ 3 % | G11: ≥ 20 % | H11: avgRateMin/Max
A12: 8 | B12: Likvidita | C12: 5 | D12: Likv. aktiva v měsících splátek | E12: váha × (1 − měs./práh) | F12: ≥ 12 měsíců | G12: 0 měsíců | H12: liquidityMonthsFull
A13: 9 | B13: Trend splácení | C13: 5 | D13: Klesá jistina + splácíš vše? | E13: 0/nesplácené×2/neklesá=max | F13: jistina klesá | G13: neklesá | H13: w.trend
A14: 10 | B14: Debt Velocity | C14: 5 | D14: Horizont splacení jistiny | E14: váha × (měs.−rychlý)/(pomalý−rychlý) | F14: ≤ 5 let | G14: ≥ 30 let | H14: velocityFast/Slow
B15: SOUČET VAH (musí být 100) | C15: =SUM(C5:C14) -> 100
A18: PARAMETRY (prahy) – editovatelné
A19: emergencyMonthsFull | B19: 6 | C19: měsíce výdajů = plná rezerva (0 stresu)
A20: interestCostMax | B20: 0.15 | C20: úroky jako podíl příjmu = max stres
A21: avgRateMin | B21: 3 | C21: vážený úrok pod = 0 stresu
A22: avgRateMax | B22: 20 | C22: vážený úrok nad = max stres
A23: liquidityMonthsFull | B23: 12 | C23: měsíce splátek kryté likviditou = 0 stresu
A24: velocityFastMonths | B24: 60 | C24: ≤ tolik měsíců do splacení = 0 stresu
A25: velocitySlowMonths | B25: 360 | C25: ≥ tolik měsíců = max stres
A26: expensiveRate | B26: 15 | C26: úrok nad = drahý dluh (%)
A28: PÁSMA CELKOVÉHO STRESU
A29: 🟢 Stabilní | B29: 0 – 29 b
A30: 🟡 Rizikové | B30: 30 – 59 b
A31: 🔴 Dluhová spirála | B31: 60 – 100 b

Sheet Bodování po rozmezích
A1: Body (stres) pro konkrétní hodnoty metrik
A2: 0 = zdravé, plná váha = max stres. Formule referencují váhy a prahy z listu „Konfigurace" – když je změníš, tabulky se přepočítají. DSTI a DTI jdou z Milanových tabulek (ukázkové řádky).
A4: Emergency Fund (váha z C6, práh B19)
A5: Rezerva (měsíce výdajů) | B5: Body (stres)
A6: 0 měs. | B6: =ROUND(MAX(0,MIN(Konfigurace!$C$6,Konfigurace!$C$6*(1-0/Konfigurace!$B$19))),1) -> 15
A7: 1 měs. | B7: =ROUND(MAX(0,MIN(Konfigurace!$C$6,Konfigurace!$C$6*(1-1/Konfigurace!$B$19))),1) -> 12.5
A8: 2 měs. | B8: =ROUND(MAX(0,MIN(Konfigurace!$C$6,Konfigurace!$C$6*(1-2/Konfigurace!$B$19))),1) -> 10
A9: 3 měs. | B9: =ROUND(MAX(0,MIN(Konfigurace!$C$6,Konfigurace!$C$6*(1-3/Konfigurace!$B$19))),1) -> 7.5
A10: 4 měs. | B10: =ROUND(MAX(0,MIN(Konfigurace!$C$6,Konfigurace!$C$6*(1-4/Konfigurace!$B$19))),1) -> 5
A11: 5 měs. | B11: =ROUND(MAX(0,MIN(Konfigurace!$C$6,Konfigurace!$C$6*(1-5/Konfigurace!$B$19))),1) -> 2.5
A12: 6 měs. | B12: =ROUND(MAX(0,MIN(Konfigurace!$C$6,Konfigurace!$C$6*(1-6/Konfigurace!$B$19))),1) -> 0
A14: Interest Cost Ratio (váha C8, práh B20)
A15: Úroky jako % příjmu | B15: Body (stres)
A16: 0 % | B16: =ROUND(MIN(Konfigurace!$C$8,Konfigurace!$C$8*0/Konfigurace!$B$20),1) -> 0
A17: 3 % | B17: =ROUND(MIN(Konfigurace!$C$8,Konfigurace!$C$8*0.03/Konfigurace!$B$20),1) -> 2
A18: 6 % | B18: =ROUND(MIN(Konfigurace!$C$8,Konfigurace!$C$8*0.06/Konfigurace!$B$20),1) -> 4
A19: 9 % | B19: =ROUND(MIN(Konfigurace!$C$8,Konfigurace!$C$8*0.09/Konfigurace!$B$20),1) -> 6
A20: 12 % | B20: =ROUND(MIN(Konfigurace!$C$8,Konfigurace!$C$8*0.12/Konfigurace!$B$20),1) -> 8
A21: 15 % | B21: =ROUND(MIN(Konfigurace!$C$8,Konfigurace!$C$8*0.15/Konfigurace!$B$20),1) -> 10
A22: 20 % | B22: =ROUND(MIN(Konfigurace!$C$8,Konfigurace!$C$8*0.2/Konfigurace!$B$20),1) -> 10
A24: Debt Quality (váha C9)
A25: Podíl drahého dluhu | B25: Body (stres)
A26: 0 % | B26: =ROUND(Konfigurace!$C$9*0,1) -> 0
A27: 25 % | B27: =ROUND(Konfigurace!$C$9*0.25,1) -> 2.5
A28: 50 % | B28: =ROUND(Konfigurace!$C$9*0.5,1) -> 5
A29: 75 % | B29: =ROUND(Konfigurace!$C$9*0.75,1) -> 7.5
A30: 100 % | B30: =ROUND(Konfigurace!$C$9*1,1) -> 10
A32: Počet půjček (váha C10)
A33: Počet půjček | B33: Body (stres)
A34: 1 | B34: =ROUND(MIN(Konfigurace!$C$10,MAX(0,(1-1)*2)),1) -> 0
A35: 2 | B35: =ROUND(MIN(Konfigurace!$C$10,MAX(0,(2-1)*2)),1) -> 2
A36: 3 | B36: =ROUND(MIN(Konfigurace!$C$10,MAX(0,(3-1)*2)),1) -> 4
A37: 4 | B37: =ROUND(MIN(Konfigurace!$C$10,MAX(0,(4-1)*2)),1) -> 6
A38: 5 | B38: =ROUND(MIN(Konfigurace!$C$10,MAX(0,(5-1)*2)),1) -> 8
A39: 6 | B39: =ROUND(MIN(Konfigurace!$C$10,MAX(0,(6-1)*2)),1) -> 8
A41: Vážený úrok (váha C11, prahy B21/B22)
A42: Vážený úrok (% p.a.) | B42: Body (stres)
A43: 3 % | B43: =ROUND(MAX(0,MIN(Konfigurace!$C$11,Konfigurace!$C$11*(3-Konfigurace!$B$21)/(Konfigurace!$B$22-Konfigurace!$B$21))),1) -> 0
A44: 6 % | B44: =ROUND(MAX(0,MIN(Konfigurace!$C$11,Konfigurace!$C$11*(6-Konfigurace!$B$21)/(Konfigurace!$B$22-Konfigurace!$B$21))),1) -> 1.2
A45: 9 % | B45: =ROUND(MAX(0,MIN(Konfigurace!$C$11,Konfigurace!$C$11*(9-Konfigurace!$B$21)/(Konfigurace!$B$22-Konfigurace!$B$21))),1) -> 2.5
...
